<?xml version="1.0"?>
<robot xmlns:xacro="http://www.ros.org/wiki/xacro">
  <!-- chassis 137.5mm x 137.5mm x 9mm -->
  <link name="chassis3">
    <inertial>
        <mass value="0.035"/>
        <origin rpy="0 0 0" xyz="0 0 0"/>
        <inertia ixx="5.537947916666668e-05" ixy="0" ixz="0" iyy="5.537947916666668e-05" iyz="0" izz="0.00011028645833333336"/>
    </inertial>

    <collision>
      <geometry>
        <box size="0.1375 0.1375 0.009"/>
      </geometry>
    </collision>

    <visual>
      <geometry>
        <box size="0.1375 0.1375 0.009"/>
      </geometry>
      <material name="box_bot_blue"/>
    </visual>
  </link>
  <joint name="chasis_2_to_chasis_3" type="fixed">
    <origin rpy="0 0 0" xyz="0 0 0.0405" />
    <parent link="chassis2" />
    <child link="chassis3" />
  </joint>

<gazebo reference="lidar_board">
    <material>Gazebo/Red</material>
</gazebo>

<gazebo reference="laser_scan_model_link">
    <material>Gazebo/BlueLaser</material>
</gazebo>


<link name="lidar_board">
  <inertial>
    <origin xyz="0 0 0" rpy="0 0 0"/>
    <mass value="0.050"/>
    <inertia ixx="3.5310093750000004e-05" ixy="0" ixz="0"
             iyy="1.5576760416666668e-05" iyz="0"
             izz="4.7766666666666664e-05"/>
  </inertial>
  <visual>
    <origin xyz="0 0 0" rpy="0 0 0"/>
    <geometry>
        <mesh filename="package://ros2_urdf_project_gazebo/meshes/sensors/lds_base.dae" scale="0.001 0.001 0.001"/>
    </geometry>
    
  </visual>
  <collision>
    <origin xyz="0 0 0" rpy="0 0 0"/>
    <geometry>
      <box size="0.058 0.090 0.01935"/>
    </geometry>
  </collision>
</link>

  <joint name="lidar_board_to_chasis_1" type="fixed">
    <origin rpy="0 0 0" xyz="0 0 0.0225" />
    <parent link="chassis3" />
    <child link="lidar_board" />
  </joint>

  <link name="lidar_mount_01">
  <inertial>
  <origin xyz="0 0 0" />
  <mass value="0.005" />
  <inertia 
      ixx="8.333333333333334e-08" ixy="0.0" ixz="0.0"
      iyy="6.376468333333333e-07" iyz="0.0" 
      izz="6.376468333333333e-07" />
</inertial>

<collision>
  <origin xyz="0 0 0" />
  <geometry>
    <box size="0.03782 0.010 0.010" />
  </geometry>
</collision>

    <visual>
    <geometry>
        <box size="0.03782 0.010 0.010" />
    </geometry>
      <material name="spacer_35mm"/>
    </visual>
  </link>

  <joint name="lidar_01_to_controlboard" type="fixed">
    <origin rpy="0 0 0" xyz="0.01009 0.0325 0.0095" />
    <parent link="chassis3" />
    <child link="lidar_mount_01" />
  </joint>

  <link name="lidar_mount_02">
  <inertial>
  <origin xyz="0 0 0" />
  <mass value="0.005" />
  <inertia 
      ixx="8.333333333333334e-08" ixy="0.0" ixz="0.0"
      iyy="6.376468333333333e-07" iyz="0.0" 
      izz="6.376468333333333e-07" />
</inertial>

<collision>
  <origin xyz="0 0 0" />
  <geometry>
    <box size="0.03782 0.010 0.010" />
  </geometry>
</collision>

    <visual>
    <geometry>
        <box size="0.03782 0.010 0.010" />
    </geometry>
      <material name="default_material"/>
    </visual>
  </link>

  <joint name="lidar_02_to_controlboard" type="fixed">
    <origin rpy="0 0 0" xyz="-0.01009 0.0325 0.0095" />
    <parent link="chassis3" />
    <child link="lidar_mount_02" />
  </joint>

  <link name="lidar_mount_03">
  <inertial>
  <origin xyz="0 0 0" />
  <mass value="0.005" />
  <inertia 
      ixx="8.333333333333334e-08" ixy="0.0" ixz="0.0"
      iyy="6.376468333333333e-07" iyz="0.0" 
      izz="6.376468333333333e-07" />
</inertial>

<collision>
  <origin xyz="0 0 0" />
  <geometry>
    <box size="0.03782 0.010 0.010" />
  </geometry>
</collision>

    <visual>
    <geometry>
        <box size="0.03782 0.010 0.010" />
    </geometry>
      <material name="spacer_35mm"/>
    </visual>
  </link>

  <joint name="lidar_03_to_controlboard" type="fixed">
    <origin rpy="0 0 0" xyz="0.01009 -0.0325 0.0095" />
    <parent link="chassis3" />
    <child link="lidar_mount_03" />
  </joint>

  <link name="lidar_mount_04">
  <inertial>
  <origin xyz="0 0 0" />
  <mass value="0.005" />
  <inertia 
      ixx="8.333333333333334e-08" ixy="0.0" ixz="0.0"
      iyy="6.376468333333333e-07" iyz="0.0" 
      izz="6.376468333333333e-07" />
</inertial>

<collision>
  <origin xyz="0 0 0" />
  <geometry>
    <box size="0.03782 0.010 0.010" />
  </geometry>
</collision>

    <visual>
    <geometry>
        <box size="0.03782 0.010 0.010" />
    </geometry>
      <material name="spacer_35mm"/>
    </visual>
  </link>

  <joint name="lidar_04_to_controlboard" type="fixed">
    <origin rpy="0 0 0" xyz="-0.01009 -0.0325 0.0095" />
    <parent link="chassis3" />
    <child link="lidar_mount_04" />
  </joint>

 <!-- Laser Position Control-->

  <link name="laser_scan_link">
    <visual>
      <origin rpy="0 0 0" xyz="0 0 0"/>
      <geometry>
        <box size="0.02 0.02 0.02"/>
      </geometry>
    </visual>

    <collision>
       <origin rpy="0 0 0" xyz="0 0 0.0204"/>
      <geometry>
        <box size="0.02 0.02 0.02"/>
      </geometry>
    </collision>

    <inertial>

      <mass value="0.01"/>
      <origin rpy="0 0 0" xyz="0 0 0.0204"/>
      <inertia ixx="6.066578520833334e-06" ixy="0" ixz="0" iyy="6.072950163333333e-06" iyz="0" izz="9.365128684166666e-06"/>
    </inertial>
  </link>

  <joint name="laser_scan_link_joint" type="prismatic">
    <origin rpy="0 0 0" xyz="0.0 0.0 0.0257"/>
    <parent link="lidar_board"/>
    <child link="laser_scan_link"/>
    <axis xyz="0 0 1"/>
    <limit lower="-0.1" upper="0.0" effort="20.0" velocity="2.0"/>
    <dynamics damping="0.1" friction="1.0"/>
  </joint>

  <link name="laser_scan_frame">
  </link>

  <joint name="laser_scan_frame_joint" type="fixed">
    <origin rpy="0 0 0" xyz="0 0 0.03"/>
    <parent link="laser_scan_link"/>
    <child link="laser_scan_frame"/>
    <axis xyz="0 0 0"/>
  </joint>


    <link name="laser_scan_model_link">
        <inertial>
        <mass value="0.050"/>
        <inertia ixx="5.493716666666667e-05" ixy="0" ixz="0" iyy="5.493716666666667e-05" iyz="0" izz="0.00010692900000000002"/>
        </inertial>
        <visual>
            <origin rpy="0 0 0" xyz="0 0 0"/>
            <geometry>
                <mesh filename="package://ros2_urdf_project_gazebo/meshes/sensors/lds_top.dae" scale="0.001 0.001 0.001"/>
            </geometry>
        </visual>
        
        <collision>
        <origin rpy="0 0 0" xyz="0 0 0.0204"/>
        <geometry>
            <cylinder radius="0.0654" length="0.0188"/>
        </geometry>
        </collision>
    </link>


  <joint name="laser_scan_model_link_joint" type="continuous">
    <origin rpy="0 0 0" xyz="0.0 0.0 0.0"/>
    <parent link="laser_scan_link"/>
    <child link="laser_scan_model_link"/>
    <axis xyz="0 0 1"/>
    <limit effort="10.0" velocity="2.0"/>
    <dynamics friction="0.01"/>
  </joint>

  <!-- Position Config -->
    <ros2_control name="GazeboSystem" type="system">
      <hardware>
        <plugin>gazebo_ros2_control/GazeboSystem</plugin>
      </hardware>

      <joint name="laser_scan_link_joint">
        <command_interface name="position">
          <param name="min">-0.05</param>
          <param name="max">0.0</param>
        </command_interface>
        <state_interface name="position"/>
        <state_interface name="velocity"/>
        <state_interface name="effort"/>
      </joint>

      <joint name="laser_scan_model_link_joint">
        <command_interface name="velocity">
          <param name="min">0.0</param>
          <param name="max">2.0</param>
        </command_interface>
        <state_interface name="position"/>
        <state_interface name="velocity"/>
        <state_interface name="effort"/>
      </joint>

  </ros2_control>


  <gazebo>
    <plugin filename="libgazebo_ros2_control.so" name="gazebo_ros2_control">
      <parameters>$(find ros2_urdf_project)/config/controller_position.yaml</parameters>
      <robot_param_node>/robot_state_publisher_node</robot_param_node>
    </plugin>
  </gazebo>

<!-- *********************** IMU SETUP *********************************  -->
<!-- Each sensor must be attached to a link.                              --> 
<joint name="imu_joint" type="fixed">
  <parent link="base_link"/>
  <child link="imu_link"/>
  <origin xyz="-0.10 0 0.05" rpy="0 0 0"/>
</joint>

<link name="imu_link"/>
<gazebo reference="imu_link">
  <sensor name="br_imu" type="imu">
    <always_on>true</always_on>
    <update_rate>100</update_rate>
    <imu>
      <angular_velocity>
        <x>
          <noise type="gaussian">
            <mean>0.0</mean>
            <stddev>2e-4</stddev>
          </noise>
        </x>
        <y>
          <noise type="gaussian">
            <mean>0.0</mean>
            <stddev>2e-4</stddev>
          </noise>
        </y>
        <z>
          <noise type="gaussian">
            <mean>0.0</mean>
            <stddev>2e-4</stddev>
          </noise>
        </z>
      </angular_velocity>
      <linear_acceleration>
        <x>
          <noise type="gaussian">
            <mean>0.0</mean>
            <stddev>1.7e-2</stddev>
          </noise>
        </x>
        <y>
          <noise type="gaussian">
            <mean>0.0</mean>
            <stddev>1.7e-2</stddev>
          </noise>
        </y>
        <z>
          <noise type="gaussian">
            <mean>0.0</mean>
            <stddev>1.7e-2</stddev>
          </noise>
        </z>
      </linear_acceleration>
    </imu>
    <plugin name="bytes_imu" filename="libgazebo_ros_imu_sensor.so">
      <ros>
        <namespace>imu</namespace>
        <remapping>~/out:=data</remapping>
      </ros>
      <initial_orientation_as_reference>false</initial_orientation_as_reference>
    </plugin>
  </sensor>
</gazebo>
</robot>